Traceback (most recent call last):
  File "/Users/alexiacardona/.conda/envs/MCBPractical2/lib/python3.10/site-packages/jupyter_cache/executors/utils.py", line 51, in single_nb_execution
    executenb(
  File "/Users/alexiacardona/.conda/envs/MCBPractical2/lib/python3.10/site-packages/nbclient/client.py", line 1204, in execute
    return NotebookClient(nb=nb, resources=resources, km=km, **kwargs).execute()
  File "/Users/alexiacardona/.conda/envs/MCBPractical2/lib/python3.10/site-packages/nbclient/util.py", line 84, in wrapped
    return just_run(coro(*args, **kwargs))
  File "/Users/alexiacardona/.conda/envs/MCBPractical2/lib/python3.10/site-packages/nbclient/util.py", line 62, in just_run
    return loop.run_until_complete(coro)
  File "/Users/alexiacardona/.conda/envs/MCBPractical2/lib/python3.10/asyncio/base_events.py", line 646, in run_until_complete
    return future.result()
  File "/Users/alexiacardona/.conda/envs/MCBPractical2/lib/python3.10/site-packages/nbclient/client.py", line 663, in async_execute
    await self.async_execute_cell(
  File "/Users/alexiacardona/.conda/envs/MCBPractical2/lib/python3.10/site-packages/nbclient/client.py", line 965, in async_execute_cell
    await self._check_raise_for_error(cell, cell_index, exec_reply)
  File "/Users/alexiacardona/.conda/envs/MCBPractical2/lib/python3.10/site-packages/nbclient/client.py", line 862, in _check_raise_for_error
    raise CellExecutionError.from_cell_and_msg(cell, exec_reply_content)
nbclient.exceptions.CellExecutionError: An error occurred while executing the following cell:
------------------
df[df["country"] == "United Kingdom" & df["year"] == 2020]
------------------

[0;31m---------------------------------------------------------------------------[0m
[0;31mTypeError[0m                                 Traceback (most recent call last)
File [0;32m~/.conda/envs/MCBPractical2/lib/python3.10/site-packages/pandas/core/ops/array_ops.py:301[0m, in [0;36mna_logical_op[0;34m(x, y, op)[0m
[1;32m    292[0m [38;5;28;01mtry[39;00m:
[1;32m    293[0m     [38;5;66;03m# For exposition, write:[39;00m
[1;32m    294[0m     [38;5;66;03m#  yarr = isinstance(y, np.ndarray)[39;00m
[0;32m   (...)[0m
[1;32m    299[0m     [38;5;66;03m# Then Cases where this goes through without raising include:[39;00m
[1;32m    300[0m     [38;5;66;03m#  (xint or xbool) and (yint or bool)[39;00m
[0;32m--> 301[0m     result [38;5;241m=[39m [43mop[49m[43m([49m[43mx[49m[43m,[49m[43m [49m[43my[49m[43m)[49m
[1;32m    302[0m [38;5;28;01mexcept[39;00m [38;5;167;01mTypeError[39;00m:

File [0;32m~/.conda/envs/MCBPractical2/lib/python3.10/site-packages/pandas/core/roperator.py:52[0m, in [0;36mrand_[0;34m(left, right)[0m
[1;32m     51[0m [38;5;28;01mdef[39;00m [38;5;21mrand_[39m(left, right):
[0;32m---> 52[0m     [38;5;28;01mreturn[39;00m [43moperator[49m[38;5;241;43m.[39;49m[43mand_[49m[43m([49m[43mright[49m[43m,[49m[43m [49m[43mleft[49m[43m)[49m

[0;31mTypeError[0m: ufunc 'bitwise_and' not supported for the input types, and the inputs could not be safely coerced to any supported types according to the casting rule ''safe''

During handling of the above exception, another exception occurred:

[0;31mValueError[0m                                Traceback (most recent call last)
File [0;32m~/.conda/envs/MCBPractical2/lib/python3.10/site-packages/pandas/core/ops/array_ops.py:315[0m, in [0;36mna_logical_op[0;34m(x, y, op)[0m
[1;32m    314[0m [38;5;28;01mtry[39;00m:
[0;32m--> 315[0m     result [38;5;241m=[39m [43mlibops[49m[38;5;241;43m.[39;49m[43mscalar_binop[49m[43m([49m[43mx[49m[43m,[49m[43m [49m[43my[49m[43m,[49m[43m [49m[43mop[49m[43m)[49m
[1;32m    316[0m [38;5;28;01mexcept[39;00m (
[1;32m    317[0m     [38;5;167;01mTypeError[39;00m,
[1;32m    318[0m     [38;5;167;01mValueError[39;00m,
[0;32m   (...)[0m
[1;32m    321[0m     [38;5;167;01mNotImplementedError[39;00m,
[1;32m    322[0m ) [38;5;28;01mas[39;00m err:

File [0;32m~/.conda/envs/MCBPractical2/lib/python3.10/site-packages/pandas/_libs/ops.pyx:180[0m, in [0;36mpandas._libs.ops.scalar_binop[0;34m()[0m

[0;31mValueError[0m: Buffer dtype mismatch, expected 'Python object' but got 'long'

The above exception was the direct cause of the following exception:

[0;31mTypeError[0m                                 Traceback (most recent call last)
Cell [0;32mIn [10], line 1[0m
[0;32m----> 1[0m df[df[[38;5;124m"[39m[38;5;124mcountry[39m[38;5;124m"[39m] [38;5;241m==[39m [38;5;124m"[39m[38;5;124mUnited Kingdom[39m[38;5;124m"[39m [38;5;241m&[39m df[[38;5;124m"[39m[38;5;124myear[39m[38;5;124m"[39m] [38;5;241m==[39m [38;5;241m2020[39m]

File [0;32m~/.conda/envs/MCBPractical2/lib/python3.10/site-packages/pandas/core/ops/common.py:70[0m, in [0;36m_unpack_zerodim_and_defer.<locals>.new_method[0;34m(self, other)[0m
[1;32m     66[0m             [38;5;28;01mreturn[39;00m [38;5;28mNotImplemented[39m
[1;32m     68[0m other [38;5;241m=[39m item_from_zerodim(other)
[0;32m---> 70[0m [38;5;28;01mreturn[39;00m [43mmethod[49m[43m([49m[38;5;28;43mself[39;49m[43m,[49m[43m [49m[43mother[49m[43m)[49m

File [0;32m~/.conda/envs/MCBPractical2/lib/python3.10/site-packages/pandas/core/arraylike.py:74[0m, in [0;36mOpsMixin.__rand__[0;34m(self, other)[0m
[1;32m     72[0m [38;5;129m@unpack_zerodim_and_defer[39m([38;5;124m"[39m[38;5;124m__rand__[39m[38;5;124m"[39m)
[1;32m     73[0m [38;5;28;01mdef[39;00m [38;5;21m__rand__[39m([38;5;28mself[39m, other):
[0;32m---> 74[0m     [38;5;28;01mreturn[39;00m [38;5;28;43mself[39;49m[38;5;241;43m.[39;49m[43m_logical_method[49m[43m([49m[43mother[49m[43m,[49m[43m [49m[43mroperator[49m[38;5;241;43m.[39;49m[43mrand_[49m[43m)[49m

File [0;32m~/.conda/envs/MCBPractical2/lib/python3.10/site-packages/pandas/core/series.py:5634[0m, in [0;36mSeries._logical_method[0;34m(self, other, op)[0m
[1;32m   5631[0m lvalues [38;5;241m=[39m [38;5;28mself[39m[38;5;241m.[39m_values
[1;32m   5632[0m rvalues [38;5;241m=[39m extract_array(other, extract_numpy[38;5;241m=[39m[38;5;28;01mTrue[39;00m, extract_range[38;5;241m=[39m[38;5;28;01mTrue[39;00m)
[0;32m-> 5634[0m res_values [38;5;241m=[39m [43mops[49m[38;5;241;43m.[39;49m[43mlogical_op[49m[43m([49m[43mlvalues[49m[43m,[49m[43m [49m[43mrvalues[49m[43m,[49m[43m [49m[43mop[49m[43m)[49m
[1;32m   5635[0m [38;5;28;01mreturn[39;00m [38;5;28mself[39m[38;5;241m.[39m_construct_result(res_values, name[38;5;241m=[39mres_name)

File [0;32m~/.conda/envs/MCBPractical2/lib/python3.10/site-packages/pandas/core/ops/array_ops.py:391[0m, in [0;36mlogical_op[0;34m(left, right, op)[0m
[1;32m    387[0m [38;5;66;03m# For int vs int `^`, `|`, `&` are bitwise operators and return[39;00m
[1;32m    388[0m [38;5;66;03m#   integer dtypes.  Otherwise these are boolean ops[39;00m
[1;32m    389[0m filler [38;5;241m=[39m fill_int [38;5;28;01mif[39;00m is_self_int_dtype [38;5;129;01mand[39;00m is_other_int_dtype [38;5;28;01melse[39;00m fill_bool
[0;32m--> 391[0m res_values [38;5;241m=[39m [43mna_logical_op[49m[43m([49m[43mlvalues[49m[43m,[49m[43m [49m[43mrvalues[49m[43m,[49m[43m [49m[43mop[49m[43m)[49m
[1;32m    392[0m [38;5;66;03m# error: Cannot call function of unknown type[39;00m
[1;32m    393[0m res_values [38;5;241m=[39m filler(res_values)  [38;5;66;03m# type: ignore[operator][39;00m

File [0;32m~/.conda/envs/MCBPractical2/lib/python3.10/site-packages/pandas/core/ops/array_ops.py:324[0m, in [0;36mna_logical_op[0;34m(x, y, op)[0m
[1;32m    316[0m         [38;5;28;01mexcept[39;00m (
[1;32m    317[0m             [38;5;167;01mTypeError[39;00m,
[1;32m    318[0m             [38;5;167;01mValueError[39;00m,
[0;32m   (...)[0m
[1;32m    321[0m             [38;5;167;01mNotImplementedError[39;00m,
[1;32m    322[0m         ) [38;5;28;01mas[39;00m err:
[1;32m    323[0m             typ [38;5;241m=[39m [38;5;28mtype[39m(y)[38;5;241m.[39m[38;5;18m__name__[39m
[0;32m--> 324[0m             [38;5;28;01mraise[39;00m [38;5;167;01mTypeError[39;00m(
[1;32m    325[0m                 [38;5;124mf[39m[38;5;124m"[39m[38;5;124mCannot perform [39m[38;5;124m'[39m[38;5;132;01m{[39;00mop[38;5;241m.[39m[38;5;18m__name__[39m[38;5;132;01m}[39;00m[38;5;124m'[39m[38;5;124m with a dtyped [[39m[38;5;132;01m{[39;00mx[38;5;241m.[39mdtype[38;5;132;01m}[39;00m[38;5;124m] array [39m[38;5;124m"[39m
[1;32m    326[0m                 [38;5;124mf[39m[38;5;124m"[39m[38;5;124mand scalar of type [[39m[38;5;132;01m{[39;00mtyp[38;5;132;01m}[39;00m[38;5;124m][39m[38;5;124m"[39m
[1;32m    327[0m             ) [38;5;28;01mfrom[39;00m [38;5;21;01merr[39;00m
[1;32m    329[0m [38;5;28;01mreturn[39;00m result[38;5;241m.[39mreshape(x[38;5;241m.[39mshape)

[0;31mTypeError[0m: Cannot perform 'rand_' with a dtyped [int64] array and scalar of type [bool]
TypeError: Cannot perform 'rand_' with a dtyped [int64] array and scalar of type [bool]

